2024-08-21 12:22:13,250 - root - ERROR - Exception while checking version: 'DeepFaceController' object has no attribute 'check_version' - Traceback (most recent call last):
  File "C:\inetpub\wwwroot\Face_Recognition\.\core\service.py", line 27, in check_version
    version = deepface_controller.check_version()
AttributeError: 'DeepFaceController' object has no attribute 'check_version'

2024-08-21 12:22:13,250 - root - ERROR - Exception while checking version: 'DeepFaceController' object has no attribute 'check_version' - Traceback (most recent call last):
  File "C:\inetpub\wwwroot\Face_Recognition\.\core\service.py", line 27, in check_version
    version = deepface_controller.check_version()
AttributeError: 'DeepFaceController' object has no attribute 'check_version'

2024-08-21 12:22:13,250 - root - ERROR - Exception while checking version: 'DeepFaceController' object has no attribute 'check_version' - Traceback (most recent call last):
  File "C:\inetpub\wwwroot\Face_Recognition\.\core\service.py", line 27, in check_version
    version = deepface_controller.check_version()
AttributeError: 'DeepFaceController' object has no attribute 'check_version'

2024-08-21 12:22:13,250 - root - ERROR - Exception while checking version: 'DeepFaceController' object has no attribute 'check_version' - Traceback (most recent call last):
  File "C:\inetpub\wwwroot\Face_Recognition\.\core\service.py", line 27, in check_version
    version = deepface_controller.check_version()
AttributeError: 'DeepFaceController' object has no attribute 'check_version'

2024-08-21 12:22:13,250 - root - ERROR - Exception while checking version: 'DeepFaceController' object has no attribute 'check_version' - Traceback (most recent call last):
  File "C:\inetpub\wwwroot\Face_Recognition\.\core\service.py", line 27, in check_version
    version = deepface_controller.check_version()
AttributeError: 'DeepFaceController' object has no attribute 'check_version'

2024-08-21 12:29:49,947 - root - ERROR - Exception while checking version: 'DeepFaceController' object has no attribute 'check_version' - Traceback (most recent call last):
  File "C:\inetpub\wwwroot\Face_Recognition\.\core\service.py", line 27, in check_version
    version = deepface_controller.check_version()
AttributeError: 'DeepFaceController' object has no attribute 'check_version'

2024-08-21 12:29:49,947 - root - ERROR - Exception while checking version: 'DeepFaceController' object has no attribute 'check_version' - Traceback (most recent call last):
  File "C:\inetpub\wwwroot\Face_Recognition\.\core\service.py", line 27, in check_version
    version = deepface_controller.check_version()
AttributeError: 'DeepFaceController' object has no attribute 'check_version'

2024-08-21 12:29:49,947 - root - ERROR - Exception while checking version: 'DeepFaceController' object has no attribute 'check_version' - Traceback (most recent call last):
  File "C:\inetpub\wwwroot\Face_Recognition\.\core\service.py", line 27, in check_version
    version = deepface_controller.check_version()
AttributeError: 'DeepFaceController' object has no attribute 'check_version'

2024-08-21 12:29:49,947 - root - ERROR - Exception while checking version: 'DeepFaceController' object has no attribute 'check_version' - Traceback (most recent call last):
  File "C:\inetpub\wwwroot\Face_Recognition\.\core\service.py", line 27, in check_version
    version = deepface_controller.check_version()
AttributeError: 'DeepFaceController' object has no attribute 'check_version'

2024-08-21 12:29:49,947 - root - ERROR - Exception while checking version: 'DeepFaceController' object has no attribute 'check_version' - Traceback (most recent call last):
  File "C:\inetpub\wwwroot\Face_Recognition\.\core\service.py", line 27, in check_version
    version = deepface_controller.check_version()
AttributeError: 'DeepFaceController' object has no attribute 'check_version'

2024-08-21 12:31:07,869 - root - ERROR - Exception while checking version: 'DeepFaceController' object has no attribute 'check_version' - Traceback (most recent call last):
  File "C:\inetpub\wwwroot\Face_Recognition\.\core\service.py", line 27, in check_version
    version = deepface_controller.check_version()
AttributeError: 'DeepFaceController' object has no attribute 'check_version'

2024-08-21 12:31:07,869 - root - ERROR - Exception while checking version: 'DeepFaceController' object has no attribute 'check_version' - Traceback (most recent call last):
  File "C:\inetpub\wwwroot\Face_Recognition\.\core\service.py", line 27, in check_version
    version = deepface_controller.check_version()
AttributeError: 'DeepFaceController' object has no attribute 'check_version'

2024-08-21 12:31:07,869 - root - ERROR - Exception while checking version: 'DeepFaceController' object has no attribute 'check_version' - Traceback (most recent call last):
  File "C:\inetpub\wwwroot\Face_Recognition\.\core\service.py", line 27, in check_version
    version = deepface_controller.check_version()
AttributeError: 'DeepFaceController' object has no attribute 'check_version'

2024-08-21 12:31:07,869 - root - ERROR - Exception while checking version: 'DeepFaceController' object has no attribute 'check_version' - Traceback (most recent call last):
  File "C:\inetpub\wwwroot\Face_Recognition\.\core\service.py", line 27, in check_version
    version = deepface_controller.check_version()
AttributeError: 'DeepFaceController' object has no attribute 'check_version'

2024-08-21 12:31:07,869 - root - ERROR - Exception while checking version: 'DeepFaceController' object has no attribute 'check_version' - Traceback (most recent call last):
  File "C:\inetpub\wwwroot\Face_Recognition\.\core\service.py", line 27, in check_version
    version = deepface_controller.check_version()
AttributeError: 'DeepFaceController' object has no attribute 'check_version'

2024-08-21 13:10:20,016 - root - ERROR - Exception while checking version: 'DeepFaceController' object has no attribute 'check_version' - Traceback (most recent call last):
  File "C:\inetpub\wwwroot\Face_Recognition\.\core\service.py", line 27, in check_version
    version = deepface_controller.check_version()
AttributeError: 'DeepFaceController' object has no attribute 'check_version'

2024-08-21 13:10:20,016 - root - ERROR - Exception while checking version: 'DeepFaceController' object has no attribute 'check_version' - Traceback (most recent call last):
  File "C:\inetpub\wwwroot\Face_Recognition\.\core\service.py", line 27, in check_version
    version = deepface_controller.check_version()
AttributeError: 'DeepFaceController' object has no attribute 'check_version'

2024-08-21 13:10:20,016 - root - ERROR - Exception while checking version: 'DeepFaceController' object has no attribute 'check_version' - Traceback (most recent call last):
  File "C:\inetpub\wwwroot\Face_Recognition\.\core\service.py", line 27, in check_version
    version = deepface_controller.check_version()
AttributeError: 'DeepFaceController' object has no attribute 'check_version'

2024-08-21 13:10:20,016 - root - ERROR - Exception while checking version: 'DeepFaceController' object has no attribute 'check_version' - Traceback (most recent call last):
  File "C:\inetpub\wwwroot\Face_Recognition\.\core\service.py", line 27, in check_version
    version = deepface_controller.check_version()
AttributeError: 'DeepFaceController' object has no attribute 'check_version'

2024-08-21 13:10:20,016 - root - ERROR - Exception while checking version: 'DeepFaceController' object has no attribute 'check_version' - Traceback (most recent call last):
  File "C:\inetpub\wwwroot\Face_Recognition\.\core\service.py", line 27, in check_version
    version = deepface_controller.check_version()
AttributeError: 'DeepFaceController' object has no attribute 'check_version'

2024-08-21 13:14:35,761 - root - ERROR - Exception while checking version: check_version() takes 0 positional arguments but 1 was given - Traceback (most recent call last):
  File "C:\inetpub\wwwroot\Face_Recognition\.\core\service.py", line 27, in check_version
    version = deepface_controller.check_version()
TypeError: check_version() takes 0 positional arguments but 1 was given

2024-08-21 13:14:35,761 - root - ERROR - Exception while checking version: check_version() takes 0 positional arguments but 1 was given - Traceback (most recent call last):
  File "C:\inetpub\wwwroot\Face_Recognition\.\core\service.py", line 27, in check_version
    version = deepface_controller.check_version()
TypeError: check_version() takes 0 positional arguments but 1 was given

2024-08-21 13:14:35,761 - root - ERROR - Exception while checking version: check_version() takes 0 positional arguments but 1 was given - Traceback (most recent call last):
  File "C:\inetpub\wwwroot\Face_Recognition\.\core\service.py", line 27, in check_version
    version = deepface_controller.check_version()
TypeError: check_version() takes 0 positional arguments but 1 was given

2024-08-21 13:14:35,761 - root - ERROR - Exception while checking version: check_version() takes 0 positional arguments but 1 was given - Traceback (most recent call last):
  File "C:\inetpub\wwwroot\Face_Recognition\.\core\service.py", line 27, in check_version
    version = deepface_controller.check_version()
TypeError: check_version() takes 0 positional arguments but 1 was given

2024-08-21 13:14:35,761 - root - ERROR - Exception while checking version: check_version() takes 0 positional arguments but 1 was given - Traceback (most recent call last):
  File "C:\inetpub\wwwroot\Face_Recognition\.\core\service.py", line 27, in check_version
    version = deepface_controller.check_version()
TypeError: check_version() takes 0 positional arguments but 1 was given

2024-08-21 13:15:16,379 - root - ERROR - Exception while checking version: check_version() takes 0 positional arguments but 1 was given - Traceback (most recent call last):
  File "C:\inetpub\wwwroot\Face_Recognition\core\service.py", line 27, in check_version
    version = deepface_controller.check_version()
TypeError: check_version() takes 0 positional arguments but 1 was given

2024-08-21 13:15:16,379 - root - ERROR - Exception while checking version: check_version() takes 0 positional arguments but 1 was given - Traceback (most recent call last):
  File "C:\inetpub\wwwroot\Face_Recognition\core\service.py", line 27, in check_version
    version = deepface_controller.check_version()
TypeError: check_version() takes 0 positional arguments but 1 was given

2024-08-21 13:15:16,379 - root - ERROR - Exception while checking version: check_version() takes 0 positional arguments but 1 was given - Traceback (most recent call last):
  File "C:\inetpub\wwwroot\Face_Recognition\core\service.py", line 27, in check_version
    version = deepface_controller.check_version()
TypeError: check_version() takes 0 positional arguments but 1 was given

2024-08-21 13:15:16,379 - root - ERROR - Exception while checking version: check_version() takes 0 positional arguments but 1 was given - Traceback (most recent call last):
  File "C:\inetpub\wwwroot\Face_Recognition\core\service.py", line 27, in check_version
    version = deepface_controller.check_version()
TypeError: check_version() takes 0 positional arguments but 1 was given

2024-08-21 13:15:16,379 - root - ERROR - Exception while checking version: check_version() takes 0 positional arguments but 1 was given - Traceback (most recent call last):
  File "C:\inetpub\wwwroot\Face_Recognition\core\service.py", line 27, in check_version
    version = deepface_controller.check_version()
TypeError: check_version() takes 0 positional arguments but 1 was given

2024-08-21 15:00:46,975 - core.utils.database - ERROR - Failed to commit transaction: cannot commit - no transaction is active
2024-08-21 15:00:46,975 - core.utils.database - ERROR - Failed to commit transaction: cannot commit - no transaction is active
2024-08-21 15:00:46,975 - core.utils.database - ERROR - Failed to commit transaction: cannot commit - no transaction is active
2024-08-21 15:00:46,975 - core.utils.database - ERROR - Failed to commit transaction: cannot commit - no transaction is active
2024-08-21 15:00:46,975 - core.utils.database - ERROR - Failed to commit transaction: cannot commit - no transaction is active
2024-08-21 15:00:46,986 - root - ERROR - Exception during background processing for UID thanhtan2136-1: cannot rollback - no transaction is active - Traceback (most recent call last):
  File "C:\inetpub\wwwroot\Face_Recognition\.\core\utils\database.py", line 202, in __exit__
    conn.execute("COMMIT")
sqlite3.OperationalError: cannot commit - no transaction is active

During handling of the above exception, another exception occurred:

Traceback (most recent call last):
  File "C:\inetpub\wwwroot\Face_Recognition\.\core\service.py", line 106, in handle_background_tasks
    db_manager.delete_oldest_embeddings(
  File "C:\inetpub\wwwroot\Face_Recognition\.\core\utils\database.py", line 132, in delete_oldest_embeddings
    conn.executemany(
  File "C:\inetpub\wwwroot\Face_Recognition\.\core\utils\database.py", line 205, in __exit__
    conn.execute("ROLLBACK")
sqlite3.OperationalError: cannot rollback - no transaction is active

2024-08-21 15:00:46,986 - root - ERROR - Exception during background processing for UID thanhtan2136-1: cannot rollback - no transaction is active - Traceback (most recent call last):
  File "C:\inetpub\wwwroot\Face_Recognition\.\core\utils\database.py", line 202, in __exit__
    conn.execute("COMMIT")
sqlite3.OperationalError: cannot commit - no transaction is active

During handling of the above exception, another exception occurred:

Traceback (most recent call last):
  File "C:\inetpub\wwwroot\Face_Recognition\.\core\service.py", line 106, in handle_background_tasks
    db_manager.delete_oldest_embeddings(
  File "C:\inetpub\wwwroot\Face_Recognition\.\core\utils\database.py", line 132, in delete_oldest_embeddings
    conn.executemany(
  File "C:\inetpub\wwwroot\Face_Recognition\.\core\utils\database.py", line 205, in __exit__
    conn.execute("ROLLBACK")
sqlite3.OperationalError: cannot rollback - no transaction is active

2024-08-21 15:00:46,986 - root - ERROR - Exception during background processing for UID thanhtan2136-1: cannot rollback - no transaction is active - Traceback (most recent call last):
  File "C:\inetpub\wwwroot\Face_Recognition\.\core\utils\database.py", line 202, in __exit__
    conn.execute("COMMIT")
sqlite3.OperationalError: cannot commit - no transaction is active

During handling of the above exception, another exception occurred:

Traceback (most recent call last):
  File "C:\inetpub\wwwroot\Face_Recognition\.\core\service.py", line 106, in handle_background_tasks
    db_manager.delete_oldest_embeddings(
  File "C:\inetpub\wwwroot\Face_Recognition\.\core\utils\database.py", line 132, in delete_oldest_embeddings
    conn.executemany(
  File "C:\inetpub\wwwroot\Face_Recognition\.\core\utils\database.py", line 205, in __exit__
    conn.execute("ROLLBACK")
sqlite3.OperationalError: cannot rollback - no transaction is active

2024-08-21 15:00:46,986 - root - ERROR - Exception during background processing for UID thanhtan2136-1: cannot rollback - no transaction is active - Traceback (most recent call last):
  File "C:\inetpub\wwwroot\Face_Recognition\.\core\utils\database.py", line 202, in __exit__
    conn.execute("COMMIT")
sqlite3.OperationalError: cannot commit - no transaction is active

During handling of the above exception, another exception occurred:

Traceback (most recent call last):
  File "C:\inetpub\wwwroot\Face_Recognition\.\core\service.py", line 106, in handle_background_tasks
    db_manager.delete_oldest_embeddings(
  File "C:\inetpub\wwwroot\Face_Recognition\.\core\utils\database.py", line 132, in delete_oldest_embeddings
    conn.executemany(
  File "C:\inetpub\wwwroot\Face_Recognition\.\core\utils\database.py", line 205, in __exit__
    conn.execute("ROLLBACK")
sqlite3.OperationalError: cannot rollback - no transaction is active

2024-08-21 15:00:46,986 - root - ERROR - Exception during background processing for UID thanhtan2136-1: cannot rollback - no transaction is active - Traceback (most recent call last):
  File "C:\inetpub\wwwroot\Face_Recognition\.\core\utils\database.py", line 202, in __exit__
    conn.execute("COMMIT")
sqlite3.OperationalError: cannot commit - no transaction is active

During handling of the above exception, another exception occurred:

Traceback (most recent call last):
  File "C:\inetpub\wwwroot\Face_Recognition\.\core\service.py", line 106, in handle_background_tasks
    db_manager.delete_oldest_embeddings(
  File "C:\inetpub\wwwroot\Face_Recognition\.\core\utils\database.py", line 132, in delete_oldest_embeddings
    conn.executemany(
  File "C:\inetpub\wwwroot\Face_Recognition\.\core\utils\database.py", line 205, in __exit__
    conn.execute("ROLLBACK")
sqlite3.OperationalError: cannot rollback - no transaction is active

2024-08-21 15:01:06,000 - core.utils.database - ERROR - Failed to commit transaction: cannot commit - no transaction is active
2024-08-21 15:01:06,000 - core.utils.database - ERROR - Failed to commit transaction: cannot commit - no transaction is active
2024-08-21 15:01:06,000 - core.utils.database - ERROR - Failed to commit transaction: cannot commit - no transaction is active
2024-08-21 15:01:06,000 - core.utils.database - ERROR - Failed to commit transaction: cannot commit - no transaction is active
2024-08-21 15:01:06,000 - core.utils.database - ERROR - Failed to commit transaction: cannot commit - no transaction is active
2024-08-21 15:01:06,007 - root - ERROR - Exception during background processing for UID thanhtan2136-2: cannot rollback - no transaction is active - Traceback (most recent call last):
  File "C:\inetpub\wwwroot\Face_Recognition\.\core\utils\database.py", line 202, in __exit__
    conn.execute("COMMIT")
sqlite3.OperationalError: cannot commit - no transaction is active

During handling of the above exception, another exception occurred:

Traceback (most recent call last):
  File "C:\inetpub\wwwroot\Face_Recognition\.\core\service.py", line 106, in handle_background_tasks
    db_manager.delete_oldest_embeddings(
  File "C:\inetpub\wwwroot\Face_Recognition\.\core\utils\database.py", line 132, in delete_oldest_embeddings
    conn.executemany(
  File "C:\inetpub\wwwroot\Face_Recognition\.\core\utils\database.py", line 205, in __exit__
    conn.execute("ROLLBACK")
sqlite3.OperationalError: cannot rollback - no transaction is active

2024-08-21 15:01:06,007 - root - ERROR - Exception during background processing for UID thanhtan2136-2: cannot rollback - no transaction is active - Traceback (most recent call last):
  File "C:\inetpub\wwwroot\Face_Recognition\.\core\utils\database.py", line 202, in __exit__
    conn.execute("COMMIT")
sqlite3.OperationalError: cannot commit - no transaction is active

During handling of the above exception, another exception occurred:

Traceback (most recent call last):
  File "C:\inetpub\wwwroot\Face_Recognition\.\core\service.py", line 106, in handle_background_tasks
    db_manager.delete_oldest_embeddings(
  File "C:\inetpub\wwwroot\Face_Recognition\.\core\utils\database.py", line 132, in delete_oldest_embeddings
    conn.executemany(
  File "C:\inetpub\wwwroot\Face_Recognition\.\core\utils\database.py", line 205, in __exit__
    conn.execute("ROLLBACK")
sqlite3.OperationalError: cannot rollback - no transaction is active

2024-08-21 15:01:06,007 - root - ERROR - Exception during background processing for UID thanhtan2136-2: cannot rollback - no transaction is active - Traceback (most recent call last):
  File "C:\inetpub\wwwroot\Face_Recognition\.\core\utils\database.py", line 202, in __exit__
    conn.execute("COMMIT")
sqlite3.OperationalError: cannot commit - no transaction is active

During handling of the above exception, another exception occurred:

Traceback (most recent call last):
  File "C:\inetpub\wwwroot\Face_Recognition\.\core\service.py", line 106, in handle_background_tasks
    db_manager.delete_oldest_embeddings(
  File "C:\inetpub\wwwroot\Face_Recognition\.\core\utils\database.py", line 132, in delete_oldest_embeddings
    conn.executemany(
  File "C:\inetpub\wwwroot\Face_Recognition\.\core\utils\database.py", line 205, in __exit__
    conn.execute("ROLLBACK")
sqlite3.OperationalError: cannot rollback - no transaction is active

2024-08-21 15:01:06,007 - root - ERROR - Exception during background processing for UID thanhtan2136-2: cannot rollback - no transaction is active - Traceback (most recent call last):
  File "C:\inetpub\wwwroot\Face_Recognition\.\core\utils\database.py", line 202, in __exit__
    conn.execute("COMMIT")
sqlite3.OperationalError: cannot commit - no transaction is active

During handling of the above exception, another exception occurred:

Traceback (most recent call last):
  File "C:\inetpub\wwwroot\Face_Recognition\.\core\service.py", line 106, in handle_background_tasks
    db_manager.delete_oldest_embeddings(
  File "C:\inetpub\wwwroot\Face_Recognition\.\core\utils\database.py", line 132, in delete_oldest_embeddings
    conn.executemany(
  File "C:\inetpub\wwwroot\Face_Recognition\.\core\utils\database.py", line 205, in __exit__
    conn.execute("ROLLBACK")
sqlite3.OperationalError: cannot rollback - no transaction is active

2024-08-21 15:01:06,007 - root - ERROR - Exception during background processing for UID thanhtan2136-2: cannot rollback - no transaction is active - Traceback (most recent call last):
  File "C:\inetpub\wwwroot\Face_Recognition\.\core\utils\database.py", line 202, in __exit__
    conn.execute("COMMIT")
sqlite3.OperationalError: cannot commit - no transaction is active

During handling of the above exception, another exception occurred:

Traceback (most recent call last):
  File "C:\inetpub\wwwroot\Face_Recognition\.\core\service.py", line 106, in handle_background_tasks
    db_manager.delete_oldest_embeddings(
  File "C:\inetpub\wwwroot\Face_Recognition\.\core\utils\database.py", line 132, in delete_oldest_embeddings
    conn.executemany(
  File "C:\inetpub\wwwroot\Face_Recognition\.\core\utils\database.py", line 205, in __exit__
    conn.execute("ROLLBACK")
sqlite3.OperationalError: cannot rollback - no transaction is active

2024-08-21 15:01:57,641 - core.utils.database - ERROR - Failed to commit transaction: cannot commit - no transaction is active
2024-08-21 15:01:57,641 - core.utils.database - ERROR - Failed to commit transaction: cannot commit - no transaction is active
2024-08-21 15:01:57,641 - core.utils.database - ERROR - Failed to commit transaction: cannot commit - no transaction is active
2024-08-21 15:01:57,641 - core.utils.database - ERROR - Failed to commit transaction: cannot commit - no transaction is active
2024-08-21 15:01:57,641 - core.utils.database - ERROR - Failed to commit transaction: cannot commit - no transaction is active
2024-08-21 15:01:57,647 - root - ERROR - Exception during background processing for UID thanhtan2136-2: cannot rollback - no transaction is active - Traceback (most recent call last):
  File "C:\inetpub\wwwroot\Face_Recognition\.\core\utils\database.py", line 202, in __exit__
    conn.execute("COMMIT")
sqlite3.OperationalError: cannot commit - no transaction is active

During handling of the above exception, another exception occurred:

Traceback (most recent call last):
  File "C:\inetpub\wwwroot\Face_Recognition\.\core\service.py", line 106, in handle_background_tasks
    db_manager.delete_oldest_embeddings(
  File "C:\inetpub\wwwroot\Face_Recognition\.\core\utils\database.py", line 132, in delete_oldest_embeddings
    conn.executemany(
  File "C:\inetpub\wwwroot\Face_Recognition\.\core\utils\database.py", line 205, in __exit__
    conn.execute("ROLLBACK")
sqlite3.OperationalError: cannot rollback - no transaction is active

2024-08-21 15:01:57,647 - root - ERROR - Exception during background processing for UID thanhtan2136-2: cannot rollback - no transaction is active - Traceback (most recent call last):
  File "C:\inetpub\wwwroot\Face_Recognition\.\core\utils\database.py", line 202, in __exit__
    conn.execute("COMMIT")
sqlite3.OperationalError: cannot commit - no transaction is active

During handling of the above exception, another exception occurred:

Traceback (most recent call last):
  File "C:\inetpub\wwwroot\Face_Recognition\.\core\service.py", line 106, in handle_background_tasks
    db_manager.delete_oldest_embeddings(
  File "C:\inetpub\wwwroot\Face_Recognition\.\core\utils\database.py", line 132, in delete_oldest_embeddings
    conn.executemany(
  File "C:\inetpub\wwwroot\Face_Recognition\.\core\utils\database.py", line 205, in __exit__
    conn.execute("ROLLBACK")
sqlite3.OperationalError: cannot rollback - no transaction is active

2024-08-21 15:01:57,647 - root - ERROR - Exception during background processing for UID thanhtan2136-2: cannot rollback - no transaction is active - Traceback (most recent call last):
  File "C:\inetpub\wwwroot\Face_Recognition\.\core\utils\database.py", line 202, in __exit__
    conn.execute("COMMIT")
sqlite3.OperationalError: cannot commit - no transaction is active

During handling of the above exception, another exception occurred:

Traceback (most recent call last):
  File "C:\inetpub\wwwroot\Face_Recognition\.\core\service.py", line 106, in handle_background_tasks
    db_manager.delete_oldest_embeddings(
  File "C:\inetpub\wwwroot\Face_Recognition\.\core\utils\database.py", line 132, in delete_oldest_embeddings
    conn.executemany(
  File "C:\inetpub\wwwroot\Face_Recognition\.\core\utils\database.py", line 205, in __exit__
    conn.execute("ROLLBACK")
sqlite3.OperationalError: cannot rollback - no transaction is active

2024-08-21 15:01:57,647 - root - ERROR - Exception during background processing for UID thanhtan2136-2: cannot rollback - no transaction is active - Traceback (most recent call last):
  File "C:\inetpub\wwwroot\Face_Recognition\.\core\utils\database.py", line 202, in __exit__
    conn.execute("COMMIT")
sqlite3.OperationalError: cannot commit - no transaction is active

During handling of the above exception, another exception occurred:

Traceback (most recent call last):
  File "C:\inetpub\wwwroot\Face_Recognition\.\core\service.py", line 106, in handle_background_tasks
    db_manager.delete_oldest_embeddings(
  File "C:\inetpub\wwwroot\Face_Recognition\.\core\utils\database.py", line 132, in delete_oldest_embeddings
    conn.executemany(
  File "C:\inetpub\wwwroot\Face_Recognition\.\core\utils\database.py", line 205, in __exit__
    conn.execute("ROLLBACK")
sqlite3.OperationalError: cannot rollback - no transaction is active

2024-08-21 15:01:57,647 - root - ERROR - Exception during background processing for UID thanhtan2136-2: cannot rollback - no transaction is active - Traceback (most recent call last):
  File "C:\inetpub\wwwroot\Face_Recognition\.\core\utils\database.py", line 202, in __exit__
    conn.execute("COMMIT")
sqlite3.OperationalError: cannot commit - no transaction is active

During handling of the above exception, another exception occurred:

Traceback (most recent call last):
  File "C:\inetpub\wwwroot\Face_Recognition\.\core\service.py", line 106, in handle_background_tasks
    db_manager.delete_oldest_embeddings(
  File "C:\inetpub\wwwroot\Face_Recognition\.\core\utils\database.py", line 132, in delete_oldest_embeddings
    conn.executemany(
  File "C:\inetpub\wwwroot\Face_Recognition\.\core\utils\database.py", line 205, in __exit__
    conn.execute("ROLLBACK")
sqlite3.OperationalError: cannot rollback - no transaction is active

